[2017-05-11 13:56:19,072: ERROR/MainProcess] consumer: Cannot connect to redis://139.224.232.97:6379/5: .
Trying again in 2.00 seconds...

[2017-05-11 13:56:21,092: ERROR/MainProcess] consumer: Cannot connect to redis://139.224.232.97:6379/5: .
Trying again in 4.00 seconds...

[2017-05-11 13:56:25,113: ERROR/MainProcess] consumer: Cannot connect to redis://139.224.232.97:6379/5: .
Trying again in 6.00 seconds...

[2017-05-11 13:56:31,137: ERROR/MainProcess] consumer: Cannot connect to redis://139.224.232.97:6379/5: .
Trying again in 8.00 seconds...

[2017-05-11 13:56:39,160: ERROR/MainProcess] consumer: Cannot connect to redis://139.224.232.97:6379/5: .
Trying again in 10.00 seconds...

[2017-05-11 13:56:44,407: INFO/MainProcess] Connected to redis://127.0.0.1:6379/5
[2017-05-11 13:56:44,417: INFO/MainProcess] mingle: searching for neighbors
[2017-05-11 13:56:45,424: INFO/MainProcess] mingle: all alone
[2017-05-11 13:56:45,443: WARNING/MainProcess] celery@LAPTOP-EIDRP1PN ready.
[2017-05-11 13:58:48,023: INFO/MainProcess] Received task: tasks.login.login_task[a23f43b7-c15b-405b-b95c-c0f168e6114b]
[2017-05-11 13:58:48,785: ERROR/Worker-1] 本次账号13260956760登陆失败
[2017-05-11 13:58:48,788: INFO/MainProcess] Task tasks.login.login_task[a23f43b7-c15b-405b-b95c-c0f168e6114b] succeeded in 0.7659999999996217s: None
[2017-05-11 14:19:43,915: INFO/MainProcess] Received task: tasks.login.login_task[7740e3c9-09a4-48a9-b519-d871fd60c1a7]
[2017-05-11 14:19:44,320: ERROR/Worker-1] 本次账号18378330541登陆失败
[2017-05-11 14:19:44,322: INFO/MainProcess] Task tasks.login.login_task[7740e3c9-09a4-48a9-b519-d871fd60c1a7] succeeded in 0.40600000000085856s: None
[2017-05-11 14:32:26,120: INFO/MainProcess] Received task: tasks.login.login_task[f2cf882f-74a9-48eb-9548-b0246f4f8ca5]
[2017-05-11 14:32:26,828: ERROR/Worker-1] 本次账号18378330541登陆失败
[2017-05-11 14:32:26,831: INFO/MainProcess] Task tasks.login.login_task[f2cf882f-74a9-48eb-9548-b0246f4f8ca5] succeeded in 0.7180000000007567s: None
[2017-05-11 14:32:44,774: INFO/MainProcess] Received task: tasks.login.login_task[baed1aa9-17a5-4471-b784-03079863f672]
[2017-05-11 14:32:46,820: INFO/Worker-1] 本次登陆账号为:13338841509
[2017-05-11 14:32:46,824: INFO/MainProcess] Task tasks.login.login_task[baed1aa9-17a5-4471-b784-03079863f672] succeeded in 2.04700000000048s: None
[2017-05-11 14:43:43,920: INFO/MainProcess] Connected to redis://127.0.0.1:6379/5
[2017-05-11 14:43:43,931: INFO/MainProcess] mingle: searching for neighbors
[2017-05-11 14:43:44,938: INFO/MainProcess] mingle: all alone
[2017-05-11 14:43:44,948: WARNING/MainProcess] celery@LAPTOP-EIDRP1PN ready.
[2017-05-11 14:45:48,318: INFO/MainProcess] Received task: tasks.login.login_task[8e25512a-aea6-418a-a67c-6c459f3feef3]
[2017-05-11 14:45:50,123: INFO/Worker-1] 本次登陆账号为:13338841509
[2017-05-11 14:45:50,126: INFO/MainProcess] Task tasks.login.login_task[8e25512a-aea6-418a-a67c-6c459f3feef3] succeeded in 1.7969999999986612s: None
[2017-05-11 14:50:39,736: INFO/MainProcess] Connected to redis://127.0.0.1:6379/5
[2017-05-11 14:50:39,746: INFO/MainProcess] mingle: searching for neighbors
[2017-05-11 14:50:40,755: INFO/MainProcess] mingle: all alone
[2017-05-11 14:50:40,768: WARNING/MainProcess] celery@LAPTOP-EIDRP1PN ready.
[2017-05-11 14:50:56,748: INFO/MainProcess] Received task: tasks.login.login_task[6e6e7879-1e17-4015-b4d9-5694018a9ec5]
[2017-05-11 14:50:58,663: INFO/Worker-1] 本次登陆账号为:13338841509
[2017-05-11 14:50:58,667: INFO/MainProcess] Task tasks.login.login_task[6e6e7879-1e17-4015-b4d9-5694018a9ec5] succeeded in 1.9220000000004802s: None
[2017-05-11 15:01:01,809: INFO/MainProcess] Received task: tasks.user.crawl_person_infos[e3dfd9dd-2dfa-4b9b-b89e-38cd8f807145]
[2017-05-11 15:01:01,811: INFO/MainProcess] Received task: tasks.user.crawl_person_infos[b0b931ca-9f92-492e-befb-91024189a88c]
[2017-05-11 15:01:01,948: INFO/Worker-1] 本次抓取的url为http://weibo.com/p/1005052891529877/info?mod=pedit_more
[2017-05-11 15:01:02,164: WARNING/Worker-1] 本次取得的账号是13338841509
[2017-05-11 15:01:20,295: INFO/Worker-1] 已经成功保存ID为2891529877的用户信息
[2017-05-11 15:01:20,368: INFO/MainProcess] Task tasks.user.crawl_person_infos[e3dfd9dd-2dfa-4b9b-b89e-38cd8f807145] succeeded in 18.563000000000102s: None
[2017-05-11 15:01:20,370: INFO/MainProcess] Received task: tasks.user.crawl_person_infos[fe5e7715-e924-4c04-8e02-7ce1e1c9a17e]
[2017-05-11 15:01:20,381: INFO/Worker-1] 本次抓取的url为http://weibo.com/p/1005052709820275/info?mod=pedit_more
[2017-05-11 15:01:21,016: WARNING/Worker-1] 本次取得的账号是13338841509
[2017-05-11 15:01:39,162: INFO/Worker-1] 已经成功保存ID为2709820275的用户信息
[2017-05-11 15:01:39,224: INFO/MainProcess] Task tasks.user.crawl_person_infos[b0b931ca-9f92-492e-befb-91024189a88c] succeeded in 18.85900000000038s: None
[2017-05-11 15:01:39,228: INFO/MainProcess] Received task: tasks.user.crawl_person_infos[bf39d5b1-f3d9-4f20-a09c-46b04e102549]
[2017-05-11 15:01:39,238: INFO/Worker-1] 本次抓取的url为http://weibo.com/p/1005051195908387/info?mod=pedit_more
[2017-05-11 15:01:39,619: WARNING/Worker-1] 本次取得的账号是13338841509
[2017-05-11 15:01:57,759: INFO/Worker-1] 已经成功保存ID为1195908387的用户信息
[2017-05-11 15:01:57,816: INFO/MainProcess] Task tasks.user.crawl_person_infos[fe5e7715-e924-4c04-8e02-7ce1e1c9a17e] succeeded in 18.59400000000096s: None
[2017-05-11 15:01:57,819: INFO/MainProcess] Received task: tasks.user.crawl_person_infos[bfeea228-b6ca-4e33-9666-ec67277e8ec6]
[2017-05-11 15:01:57,829: INFO/Worker-1] 本次抓取的url为http://weibo.com/p/1005051604363024/info?mod=pedit_more
[2017-05-11 15:01:58,406: WARNING/Worker-1] 本次取得的账号是13338841509
[2017-05-11 15:02:16,495: INFO/Worker-1] 本次抓取的url为http://weibo.com/p/1035051604363024/info?mod=pedit_more
[2017-05-11 15:02:16,736: WARNING/Worker-1] 本次取得的账号是13338841509
[2017-05-11 15:02:34,877: INFO/Worker-1] 已经成功保存ID为1604363024的用户信息
[2017-05-11 15:02:34,935: INFO/MainProcess] Task tasks.user.crawl_person_infos[bf39d5b1-f3d9-4f20-a09c-46b04e102549] succeeded in 37.10899999999856s: None
[2017-05-11 15:02:34,938: INFO/MainProcess] Received task: tasks.user.crawl_person_infos[ccedb84f-d15f-4da4-9ea7-3c3215aca718]
[2017-05-11 15:02:34,947: INFO/Worker-1] 本次抓取的url为http://weibo.com/p/10050510503/info?mod=pedit_more
[2017-05-11 15:02:35,501: WARNING/Worker-1] 本次取得的账号是13338841509
[2017-05-11 15:02:53,635: INFO/Worker-1] 已经成功保存ID为10503的用户信息
[2017-05-11 15:02:53,692: INFO/MainProcess] Task tasks.user.crawl_person_infos[bfeea228-b6ca-4e33-9666-ec67277e8ec6] succeeded in 18.76600000000144s: None
[2017-05-11 15:02:53,696: INFO/MainProcess] Received task: tasks.user.crawl_person_infos[a727f787-c9f3-4de0-929b-5f7b78cf3282]
[2017-05-11 15:02:53,705: INFO/Worker-1] 本次抓取的url为http://weibo.com/p/1005051819309485/info?mod=pedit_more
[2017-05-11 15:02:54,014: WARNING/Worker-1] 本次取得的账号是13338841509
[2017-05-11 15:03:12,155: INFO/Worker-1] 已经成功保存ID为1819309485的用户信息
[2017-05-11 15:03:12,219: INFO/MainProcess] Task tasks.user.crawl_person_infos[ccedb84f-d15f-4da4-9ea7-3c3215aca718] succeeded in 18.514999999999418s: None
[2017-05-11 15:03:12,223: INFO/MainProcess] Received task: tasks.user.crawl_person_infos[6e36aabb-0e5d-4fe5-890a-c1dc66542e5b]
[2017-05-11 15:03:12,233: INFO/Worker-1] 本次抓取的url为http://weibo.com/p/1005051853923717/info?mod=pedit_more
[2017-05-11 15:03:12,956: WARNING/Worker-1] 本次取得的账号是13338841509
[2017-05-11 15:03:31,158: INFO/Worker-1] 已经成功保存ID为1853923717的用户信息
[2017-05-11 15:03:31,257: INFO/MainProcess] Task tasks.user.crawl_person_infos[a727f787-c9f3-4de0-929b-5f7b78cf3282] succeeded in 19.03100000000086s: None
[2017-05-11 15:03:31,259: INFO/MainProcess] Received task: tasks.user.crawl_person_infos[c21f5c2c-d2f6-4a44-93e2-43201f5575e0]
[2017-05-11 15:03:31,270: INFO/Worker-1] 本次抓取的url为http://weibo.com/p/1005051565668374/info?mod=pedit_more
[2017-05-11 15:03:31,532: WARNING/Worker-1] 本次取得的账号是13338841509
[2017-05-11 15:03:49,665: INFO/Worker-1] 已经成功保存ID为1565668374的用户信息
[2017-05-11 15:03:49,720: INFO/MainProcess] Task tasks.user.crawl_person_infos[6e36aabb-0e5d-4fe5-890a-c1dc66542e5b] succeeded in 18.45299999999952s: None
[2017-05-11 15:03:49,724: INFO/MainProcess] Received task: tasks.user.crawl_person_infos[c77b097c-ff73-4246-9868-b3198a467b8f]
[2017-05-11 15:03:49,733: INFO/Worker-1] 本次抓取的url为http://weibo.com/p/1005051751401422/info?mod=pedit_more
[2017-05-11 15:03:50,080: WARNING/Worker-1] 本次取得的账号是13338841509
[2017-05-11 15:04:08,241: INFO/Worker-1] 已经成功保存ID为1751401422的用户信息
[2017-05-11 15:04:08,297: INFO/MainProcess] Task tasks.user.crawl_person_infos[c21f5c2c-d2f6-4a44-93e2-43201f5575e0] succeeded in 18.563000000000102s: None
[2017-05-11 15:04:08,300: INFO/MainProcess] Received task: tasks.user.crawl_person_infos[7bebddc2-3932-4fe0-be55-3c2e389ae61c]
[2017-05-11 15:04:08,310: INFO/Worker-1] 本次抓取的url为http://weibo.com/p/1005051758453771/info?mod=pedit_more
[2017-05-11 15:04:08,905: WARNING/Worker-1] 本次取得的账号是13338841509
[2017-05-11 15:04:27,034: INFO/Worker-1] 已经成功保存ID为1758453771的用户信息
[2017-05-11 15:04:27,391: INFO/MainProcess] Task tasks.user.crawl_person_infos[c77b097c-ff73-4246-9868-b3198a467b8f] succeeded in 19.07800000000134s: None
[2017-05-11 15:04:27,394: INFO/MainProcess] Received task: tasks.user.crawl_person_infos[0b55c4db-82f4-4e73-970d-1b6cd8ed76c0]
[2017-05-11 15:04:27,404: INFO/Worker-1] 本次抓取的url为http://weibo.com/p/1005052041028560/info?mod=pedit_more
[2017-05-11 15:04:27,735: WARNING/Worker-1] 本次取得的账号是13338841509
[2017-05-11 15:04:45,874: INFO/Worker-1] 已经成功保存ID为2041028560的用户信息
[2017-05-11 15:04:45,929: INFO/MainProcess] Task tasks.user.crawl_person_infos[7bebddc2-3932-4fe0-be55-3c2e389ae61c] succeeded in 18.53099999999904s: None
[2017-05-11 15:04:45,933: INFO/MainProcess] Received task: tasks.user.crawl_person_infos[7709e754-2175-462a-a63d-9e141a0c571d]
[2017-05-11 15:04:45,942: INFO/Worker-1] 本次抓取的url为http://weibo.com/p/1005051191258123/info?mod=pedit_more
[2017-05-11 15:04:47,107: WARNING/Worker-1] 本次取得的账号是13338841509
[2017-05-11 15:05:05,199: INFO/Worker-1] 本次抓取的url为http://weibo.com/p/1035051191258123/info?mod=pedit_more
[2017-05-11 15:05:05,411: WARNING/Worker-1] 本次取得的账号是13338841509
[2017-05-11 15:05:23,533: INFO/Worker-1] 已经成功保存ID为1191258123的用户信息
[2017-05-11 15:05:23,588: INFO/MainProcess] Task tasks.user.crawl_person_infos[0b55c4db-82f4-4e73-970d-1b6cd8ed76c0] succeeded in 37.65600000000086s: None
[2017-05-11 15:05:23,601: INFO/Worker-1] 本次抓取的url为http://weibo.com/p/1005051839256234/info?mod=pedit_more
[2017-05-11 15:05:24,937: WARNING/Worker-1] 本次取得的账号是13338841509
[2017-05-11 15:05:43,476: INFO/Worker-1] 已经成功保存ID为1839256234的用户信息
[2017-05-11 15:05:43,576: INFO/MainProcess] Task tasks.user.crawl_person_infos[7709e754-2175-462a-a63d-9e141a0c571d] succeeded in 19.985000000000582s: None
[2017-05-11 15:08:03,642: ERROR/MainProcess] Received unregistered task of type 'tasks.user.search_keyword'.
The message has been ignored and discarded.

Did you remember to import the module containing this task?
Or maybe you are using relative imports?
Please see http://bit.ly/gLye1c for more information.

The full contents of the message body was:
{'task': 'tasks.user.search_keyword', 'id': '2bbb14ff-0b17-481c-a2fe-fa293d1fa2a4', 'args': [['僵尸肉']], 'kwargs': {}, 'retries': 0, 'eta': None, 'expires': None, 'utc': True, 'callbacks': None, 'errbacks': None, 'timelimit': [None, None], 'taskset': None, 'chord': None} (284b)
Traceback (most recent call last):
  File "c:\users\zertu\appdata\local\programs\python\python36\lib\site-packages\celery\worker\consumer.py", line 465, in on_task_received
    strategies[type_](message, body,
KeyError: 'tasks.user.search_keyword'
[2017-05-11 15:08:03,646: ERROR/MainProcess] Received unregistered task of type 'tasks.user.search_keyword'.
The message has been ignored and discarded.

Did you remember to import the module containing this task?
Or maybe you are using relative imports?
Please see http://bit.ly/gLye1c for more information.

The full contents of the message body was:
{'task': 'tasks.user.search_keyword', 'id': '05f76bf9-57f9-42c9-be91-557b1a629bc2', 'args': [['饿了么黑心作坊']], 'kwargs': {}, 'retries': 0, 'eta': None, 'expires': None, 'utc': True, 'callbacks': None, 'errbacks': None, 'timelimit': [None, None], 'taskset': None, 'chord': None} (308b)
Traceback (most recent call last):
  File "c:\users\zertu\appdata\local\programs\python\python36\lib\site-packages\celery\worker\consumer.py", line 465, in on_task_received
    strategies[type_](message, body,
KeyError: 'tasks.user.search_keyword'
[2017-05-11 15:08:03,648: ERROR/MainProcess] Received unregistered task of type 'tasks.user.search_keyword'.
The message has been ignored and discarded.

Did you remember to import the module containing this task?
Or maybe you are using relative imports?
Please see http://bit.ly/gLye1c for more information.

The full contents of the message body was:
{'task': 'tasks.user.search_keyword', 'id': 'f1789421-de57-48d6-b367-32372525c978', 'args': [['黄记煌三汁焖锅再曝丑闻']], 'kwargs': {}, 'retries': 0, 'eta': None, 'expires': None, 'utc': True, 'callbacks': None, 'errbacks': None, 'timelimit': [None, None], 'taskset': None, 'chord': None} (332b)
Traceback (most recent call last):
  File "c:\users\zertu\appdata\local\programs\python\python36\lib\site-packages\celery\worker\consumer.py", line 465, in on_task_received
    strategies[type_](message, body,
KeyError: 'tasks.user.search_keyword'
[2017-05-11 15:11:58,078: ERROR/MainProcess] Received unregistered task of type 'tasks.user.search_keyword'.
The message has been ignored and discarded.

Did you remember to import the module containing this task?
Or maybe you are using relative imports?
Please see http://bit.ly/gLye1c for more information.

The full contents of the message body was:
{'task': 'tasks.user.search_keyword', 'id': 'b467626d-1823-4ddd-8432-ab1fe6d2a91c', 'args': [['僵尸肉']], 'kwargs': {}, 'retries': 0, 'eta': None, 'expires': None, 'utc': True, 'callbacks': None, 'errbacks': None, 'timelimit': [None, None], 'taskset': None, 'chord': None} (284b)
Traceback (most recent call last):
  File "c:\users\zertu\appdata\local\programs\python\python36\lib\site-packages\celery\worker\consumer.py", line 465, in on_task_received
    strategies[type_](message, body,
KeyError: 'tasks.user.search_keyword'
[2017-05-11 15:11:58,080: ERROR/MainProcess] Received unregistered task of type 'tasks.user.search_keyword'.
The message has been ignored and discarded.

Did you remember to import the module containing this task?
Or maybe you are using relative imports?
Please see http://bit.ly/gLye1c for more information.

The full contents of the message body was:
{'task': 'tasks.user.search_keyword', 'id': '620bf075-ecd7-4826-84af-62a86119ee0d', 'args': [['饿了么黑心作坊']], 'kwargs': {}, 'retries': 0, 'eta': None, 'expires': None, 'utc': True, 'callbacks': None, 'errbacks': None, 'timelimit': [None, None], 'taskset': None, 'chord': None} (308b)
Traceback (most recent call last):
  File "c:\users\zertu\appdata\local\programs\python\python36\lib\site-packages\celery\worker\consumer.py", line 465, in on_task_received
    strategies[type_](message, body,
KeyError: 'tasks.user.search_keyword'
[2017-05-11 15:11:58,083: ERROR/MainProcess] Received unregistered task of type 'tasks.user.search_keyword'.
The message has been ignored and discarded.

Did you remember to import the module containing this task?
Or maybe you are using relative imports?
Please see http://bit.ly/gLye1c for more information.

The full contents of the message body was:
{'task': 'tasks.user.search_keyword', 'id': '97c1d075-78da-48d2-9646-4bdeec044aa7', 'args': [['黄记煌三汁焖锅再曝丑闻']], 'kwargs': {}, 'retries': 0, 'eta': None, 'expires': None, 'utc': True, 'callbacks': None, 'errbacks': None, 'timelimit': [None, None], 'taskset': None, 'chord': None} (332b)
Traceback (most recent call last):
  File "c:\users\zertu\appdata\local\programs\python\python36\lib\site-packages\celery\worker\consumer.py", line 465, in on_task_received
    strategies[type_](message, body,
KeyError: 'tasks.user.search_keyword'
[2017-05-11 15:12:05,569: INFO/MainProcess] Connected to redis://127.0.0.1:6379/5
[2017-05-11 15:12:05,579: INFO/MainProcess] mingle: searching for neighbors
[2017-05-11 15:12:06,587: INFO/MainProcess] mingle: all alone
[2017-05-11 15:12:06,596: WARNING/MainProcess] celery@LAPTOP-EIDRP1PN ready.
[2017-05-11 15:12:12,726: ERROR/MainProcess] Received unregistered task of type 'tasks.user.search_keyword'.
The message has been ignored and discarded.

Did you remember to import the module containing this task?
Or maybe you are using relative imports?
Please see http://bit.ly/gLye1c for more information.

The full contents of the message body was:
{'task': 'tasks.user.search_keyword', 'id': '3a46d173-3099-4db3-951c-4f5f1f07a220', 'args': [['僵尸肉']], 'kwargs': {}, 'retries': 0, 'eta': None, 'expires': None, 'utc': True, 'callbacks': None, 'errbacks': None, 'timelimit': [None, None], 'taskset': None, 'chord': None} (284b)
Traceback (most recent call last):
  File "c:\users\zertu\appdata\local\programs\python\python36\lib\site-packages\celery\worker\consumer.py", line 465, in on_task_received
    strategies[type_](message, body,
KeyError: 'tasks.user.search_keyword'
[2017-05-11 15:12:12,729: ERROR/MainProcess] Received unregistered task of type 'tasks.user.search_keyword'.
The message has been ignored and discarded.

Did you remember to import the module containing this task?
Or maybe you are using relative imports?
Please see http://bit.ly/gLye1c for more information.

The full contents of the message body was:
{'task': 'tasks.user.search_keyword', 'id': '7be4f308-d846-4ade-84b4-4e160f086b48', 'args': [['饿了么黑心作坊']], 'kwargs': {}, 'retries': 0, 'eta': None, 'expires': None, 'utc': True, 'callbacks': None, 'errbacks': None, 'timelimit': [None, None], 'taskset': None, 'chord': None} (308b)
Traceback (most recent call last):
  File "c:\users\zertu\appdata\local\programs\python\python36\lib\site-packages\celery\worker\consumer.py", line 465, in on_task_received
    strategies[type_](message, body,
KeyError: 'tasks.user.search_keyword'
[2017-05-11 15:12:12,731: ERROR/MainProcess] Received unregistered task of type 'tasks.user.search_keyword'.
The message has been ignored and discarded.

Did you remember to import the module containing this task?
Or maybe you are using relative imports?
Please see http://bit.ly/gLye1c for more information.

The full contents of the message body was:
{'task': 'tasks.user.search_keyword', 'id': 'c434fc88-3461-4174-92d2-c85c8b39e99e', 'args': [['黄记煌三汁焖锅再曝丑闻']], 'kwargs': {}, 'retries': 0, 'eta': None, 'expires': None, 'utc': True, 'callbacks': None, 'errbacks': None, 'timelimit': [None, None], 'taskset': None, 'chord': None} (332b)
Traceback (most recent call last):
  File "c:\users\zertu\appdata\local\programs\python\python36\lib\site-packages\celery\worker\consumer.py", line 465, in on_task_received
    strategies[type_](message, body,
KeyError: 'tasks.user.search_keyword'
[2017-05-11 15:12:23,642: INFO/MainProcess] Received task: tasks.login.login_task[a2faca51-f76c-4b08-b3b4-9f9368bc5ef1]
[2017-05-11 15:12:25,466: INFO/Worker-1] 本次登陆账号为:13338841509
[2017-05-11 15:12:25,468: INFO/MainProcess] Task tasks.login.login_task[a2faca51-f76c-4b08-b3b4-9f9368bc5ef1] succeeded in 1.8119999999998981s: None
[2017-05-11 15:17:46,206: ERROR/MainProcess] Received unregistered task of type 'tasks.user.search_keyword'.
The message has been ignored and discarded.

Did you remember to import the module containing this task?
Or maybe you are using relative imports?
Please see http://bit.ly/gLye1c for more information.

The full contents of the message body was:
{'task': 'tasks.user.search_keyword', 'id': '13f47aec-f487-4759-8b4a-c54b74c5faff', 'args': [['僵尸肉']], 'kwargs': {}, 'retries': 0, 'eta': None, 'expires': None, 'utc': True, 'callbacks': None, 'errbacks': None, 'timelimit': [None, None], 'taskset': None, 'chord': None} (284b)
Traceback (most recent call last):
  File "c:\users\zertu\appdata\local\programs\python\python36\lib\site-packages\celery\worker\consumer.py", line 465, in on_task_received
    strategies[type_](message, body,
KeyError: 'tasks.user.search_keyword'
[2017-05-11 15:17:46,209: ERROR/MainProcess] Received unregistered task of type 'tasks.user.search_keyword'.
The message has been ignored and discarded.

Did you remember to import the module containing this task?
Or maybe you are using relative imports?
Please see http://bit.ly/gLye1c for more information.

The full contents of the message body was:
{'task': 'tasks.user.search_keyword', 'id': '70467827-1783-4689-a916-becd2431c64e', 'args': [['饿了么黑心作坊']], 'kwargs': {}, 'retries': 0, 'eta': None, 'expires': None, 'utc': True, 'callbacks': None, 'errbacks': None, 'timelimit': [None, None], 'taskset': None, 'chord': None} (308b)
Traceback (most recent call last):
  File "c:\users\zertu\appdata\local\programs\python\python36\lib\site-packages\celery\worker\consumer.py", line 465, in on_task_received
    strategies[type_](message, body,
KeyError: 'tasks.user.search_keyword'
[2017-05-11 15:17:46,210: ERROR/MainProcess] Received unregistered task of type 'tasks.user.search_keyword'.
The message has been ignored and discarded.

Did you remember to import the module containing this task?
Or maybe you are using relative imports?
Please see http://bit.ly/gLye1c for more information.

The full contents of the message body was:
{'task': 'tasks.user.search_keyword', 'id': '382d225f-9e2b-43fb-9ac8-541453172075', 'args': [['黄记煌三汁焖锅再曝丑闻']], 'kwargs': {}, 'retries': 0, 'eta': None, 'expires': None, 'utc': True, 'callbacks': None, 'errbacks': None, 'timelimit': [None, None], 'taskset': None, 'chord': None} (332b)
Traceback (most recent call last):
  File "c:\users\zertu\appdata\local\programs\python\python36\lib\site-packages\celery\worker\consumer.py", line 465, in on_task_received
    strategies[type_](message, body,
KeyError: 'tasks.user.search_keyword'
[2017-05-11 15:18:56,927: INFO/MainProcess] Connected to redis://127.0.0.1:6379/5
[2017-05-11 15:18:56,937: INFO/MainProcess] mingle: searching for neighbors
[2017-05-11 15:18:57,943: INFO/MainProcess] mingle: all alone
[2017-05-11 15:18:57,954: WARNING/MainProcess] celery@LAPTOP-EIDRP1PN ready.
[2017-05-11 15:19:13,384: INFO/MainProcess] Received task: tasks.login.login_task[c516d100-9683-440e-afe5-b4006e971baf]
[2017-05-11 15:19:19,600: INFO/Worker-1] 本次登陆账号为:13338841509
[2017-05-11 15:19:19,602: INFO/MainProcess] Task tasks.login.login_task[c516d100-9683-440e-afe5-b4006e971baf] succeeded in 6.218999999999141s: None
[2017-05-11 15:19:42,415: ERROR/MainProcess] Received unregistered task of type 'tasks.user.search_keyword'.
The message has been ignored and discarded.

Did you remember to import the module containing this task?
Or maybe you are using relative imports?
Please see http://bit.ly/gLye1c for more information.

The full contents of the message body was:
{'task': 'tasks.user.search_keyword', 'id': '29372fcd-8ecc-4c1c-b96e-d3361859227d', 'args': [['僵尸肉']], 'kwargs': {}, 'retries': 0, 'eta': None, 'expires': None, 'utc': True, 'callbacks': None, 'errbacks': None, 'timelimit': [None, None], 'taskset': None, 'chord': None} (284b)
Traceback (most recent call last):
  File "c:\users\zertu\appdata\local\programs\python\python36\lib\site-packages\celery\worker\consumer.py", line 465, in on_task_received
    strategies[type_](message, body,
KeyError: 'tasks.user.search_keyword'
[2017-05-11 15:19:42,417: ERROR/MainProcess] Received unregistered task of type 'tasks.user.search_keyword'.
The message has been ignored and discarded.

Did you remember to import the module containing this task?
Or maybe you are using relative imports?
Please see http://bit.ly/gLye1c for more information.

The full contents of the message body was:
{'task': 'tasks.user.search_keyword', 'id': '261c767b-95fe-4482-9a10-9170b3a696f1', 'args': [['饿了么黑心作坊']], 'kwargs': {}, 'retries': 0, 'eta': None, 'expires': None, 'utc': True, 'callbacks': None, 'errbacks': None, 'timelimit': [None, None], 'taskset': None, 'chord': None} (308b)
Traceback (most recent call last):
  File "c:\users\zertu\appdata\local\programs\python\python36\lib\site-packages\celery\worker\consumer.py", line 465, in on_task_received
    strategies[type_](message, body,
KeyError: 'tasks.user.search_keyword'
[2017-05-11 15:19:42,419: ERROR/MainProcess] Received unregistered task of type 'tasks.user.search_keyword'.
The message has been ignored and discarded.

Did you remember to import the module containing this task?
Or maybe you are using relative imports?
Please see http://bit.ly/gLye1c for more information.

The full contents of the message body was:
{'task': 'tasks.user.search_keyword', 'id': '5c61d996-fb15-40fe-89e1-e68ac9ea90bb', 'args': [['黄记煌三汁焖锅再曝丑闻']], 'kwargs': {}, 'retries': 0, 'eta': None, 'expires': None, 'utc': True, 'callbacks': None, 'errbacks': None, 'timelimit': [None, None], 'taskset': None, 'chord': None} (332b)
Traceback (most recent call last):
  File "c:\users\zertu\appdata\local\programs\python\python36\lib\site-packages\celery\worker\consumer.py", line 465, in on_task_received
    strategies[type_](message, body,
KeyError: 'tasks.user.search_keyword'
[2017-05-11 15:22:37,315: INFO/MainProcess] Connected to redis://127.0.0.1:6379/5
[2017-05-11 15:22:37,326: INFO/MainProcess] mingle: searching for neighbors
[2017-05-11 15:22:38,333: INFO/MainProcess] mingle: all alone
[2017-05-11 15:22:38,346: WARNING/MainProcess] celery@LAPTOP-EIDRP1PN ready.
[2017-05-11 15:22:43,618: INFO/MainProcess] Received task: tasks.login.login_task[2898e463-192a-4dc5-ae40-778a6842c52c]
[2017-05-11 15:22:45,557: INFO/Worker-1] 本次登陆账号为:13338841509
[2017-05-11 15:22:45,561: INFO/MainProcess] Task tasks.login.login_task[2898e463-192a-4dc5-ae40-778a6842c52c] succeeded in 1.9369999999998981s: None
[2017-05-11 15:29:12,276: INFO/MainProcess] Connected to redis://127.0.0.1:6379/5
[2017-05-11 15:29:12,284: INFO/MainProcess] mingle: searching for neighbors
[2017-05-11 15:29:13,290: INFO/MainProcess] mingle: all alone
[2017-05-11 15:29:13,301: WARNING/MainProcess] celery@LAPTOP-EIDRP1PN ready.
[2017-05-11 15:29:35,989: INFO/MainProcess] Connected to redis://127.0.0.1:6379/5
[2017-05-11 15:29:36,001: INFO/MainProcess] mingle: searching for neighbors
[2017-05-11 15:29:37,006: INFO/MainProcess] mingle: all alone
[2017-05-11 15:29:37,018: WARNING/MainProcess] celery@LAPTOP-EIDRP1PN ready.
[2017-05-11 15:29:44,876: INFO/MainProcess] Received task: tasks.login.login_task[d6c2a79d-f07d-45c0-b4a0-e81995f91758]
[2017-05-11 15:29:47,163: INFO/Worker-1] 本次登陆账号为:13338841509
[2017-05-11 15:29:47,166: INFO/MainProcess] Task tasks.login.login_task[d6c2a79d-f07d-45c0-b4a0-e81995f91758] succeeded in 2.2819999999992433s: None
[2017-05-11 15:36:20,609: INFO/MainProcess] Received task: tasks.login.login_task[c5f533ec-662a-42b5-9778-921155d1ced2]
[2017-05-11 15:36:22,354: INFO/Worker-1] 本次登陆账号为:13338841509
[2017-05-11 15:36:22,356: INFO/MainProcess] Task tasks.login.login_task[c5f533ec-662a-42b5-9778-921155d1ced2] succeeded in 1.75s: None
[2017-05-11 15:42:43,014: ERROR/MainProcess] consumer: Cannot connect to redis://127.0.0.1:6379/5: .
Trying again in 2.00 seconds...

[2017-05-11 15:42:46,127: ERROR/MainProcess] consumer: Cannot connect to redis://127.0.0.1:6379/5: .
Trying again in 4.00 seconds...

[2017-05-11 15:42:50,647: INFO/MainProcess] Connected to redis://127.0.0.1:6379/5
[2017-05-11 15:42:50,657: INFO/MainProcess] mingle: searching for neighbors
[2017-05-11 15:42:51,667: INFO/MainProcess] mingle: all alone
[2017-05-11 15:42:51,677: WARNING/MainProcess] celery@LAPTOP-EIDRP1PN ready.
[2017-05-11 15:43:20,749: INFO/MainProcess] Received task: tasks.login.login_task[74267157-79fc-411f-b725-f8e121d7abe1]
[2017-05-11 15:43:22,429: INFO/Worker-1] 本次登陆账号为:13338841509
[2017-05-11 15:43:22,429: INFO/MainProcess] Task tasks.login.login_task[74267157-79fc-411f-b725-f8e121d7abe1] succeeded in 1.6869999999980791s: None
[2017-05-11 16:59:11,081: INFO/MainProcess] Connected to redis://127.0.0.1:6379/5
[2017-05-11 16:59:11,092: INFO/MainProcess] mingle: searching for neighbors
[2017-05-11 16:59:12,099: INFO/MainProcess] mingle: all alone
[2017-05-11 16:59:12,109: WARNING/MainProcess] celery@LAPTOP-EIDRP1PN ready.
[2017-05-11 16:59:32,559: INFO/MainProcess] Received task: tasks.login.login_task[13e10b47-f4b5-4a67-bc06-78a034742f63]
[2017-05-11 16:59:34,096: INFO/Worker-1] 本次登陆账号为:13338841509
[2017-05-11 16:59:34,099: INFO/MainProcess] Task tasks.login.login_task[13e10b47-f4b5-4a67-bc06-78a034742f63] succeeded in 1.5470000000022992s: None
